Traceback (most recent call last):
  File "C:\Users\aaron\AppData\Local\Programs\Python\Python39\lib\site-packages\wandb\sdk\wandb_config.py", line 166, in __getattr__
    return self.__getitem__(key)
  File "C:\Users\aaron\AppData\Local\Programs\Python\Python39\lib\site-packages\wandb\sdk\wandb_config.py", line 133, in __getitem__
    return self._items[key]
KeyError: 'patience'
The above exception was the direct cause of the following exception:
Traceback (most recent call last):
  File "C:\Users\aaron\CODING\SCAI\train.py", line 47, in <module>
    early_stopping = tf.keras.callbacks.EarlyStopping(monitor='val_loss', min_delta=wandb.config.min_delta, patience=10)
  File "C:\Users\aaron\AppData\Local\Programs\Python\Python39\lib\site-packages\wandb\sdk\wandb_config.py", line 168, in __getattr__
    raise AttributeError(
AttributeError: '<class 'wandb.sdk.wandb_config.Config'>' object has no attribute 'patience'