Traceback (most recent call last):
  File "C:\Users\aaron\AppData\Local\Programs\Python\Python39\lib\site-packages\wandb\sdk\wandb_config.py", line 166, in __getattr__
    return self.__getitem__(key)
  File "C:\Users\aaron\AppData\Local\Programs\Python\Python39\lib\site-packages\wandb\sdk\wandb_config.py", line 133, in __getitem__
    return self._items[key]
KeyError: 'max_pool1_size'
The above exception was the direct cause of the following exception:
Traceback (most recent call last):
  File "C:\Users\aaron\CODING\SCAI\train.py", line 19, in <module>
    x = tf.keras.layers.MaxPooling2D(wandb.config.max_pool1_size)(x)
  File "C:\Users\aaron\AppData\Local\Programs\Python\Python39\lib\site-packages\wandb\sdk\wandb_config.py", line 168, in __getattr__
    raise AttributeError(
AttributeError: '<class 'wandb.sdk.wandb_config.Config'>' object has no attribute 'max_pool1_size'