2023-01-05 13:26:01,751 INFO    StreamThr :25064 [internal.py:wandb_internal():87] W&B internal server running at pid: 25064, started at: 2023-01-05 13:26:01.749186
2023-01-05 13:26:01,754 DEBUG   HandlerThread:25064 [handler.py:handle_request():139] handle_request: status
2023-01-05 13:26:01,760 DEBUG   SenderThread:25064 [sender.py:send_request():317] send_request: status
2023-01-05 13:26:01,770 DEBUG   SenderThread:25064 [sender.py:send():303] send: header
2023-01-05 13:26:01,770 INFO    WriterThread:25064 [datastore.py:open_for_write():75] open: C:\Users\aaron\CODING\SCAI\wandb\run-20230105_132601-jai16x3v\run-jai16x3v.wandb
2023-01-05 13:26:01,859 DEBUG   SenderThread:25064 [sender.py:send():303] send: run
2023-01-05 13:26:02,115 ERROR   SenderThread:25064 [internal_api.py:execute():212] 409 response executing GraphQL.
2023-01-05 13:26:02,115 ERROR   SenderThread:25064 [internal_api.py:execute():213] {"errors":[{"message":"run orbs/SCAI_Health/jai16x3v was previously created and deleted; try a new run name","path":["upsertBucket"]}],"data":{"upsertBucket":null}}
2023-01-05 13:26:03,410 ERROR   SenderThread:25064 [internal_api.py:execute():212] 409 response executing GraphQL.
2023-01-05 13:26:03,411 ERROR   SenderThread:25064 [internal_api.py:execute():213] {"errors":[{"message":"run orbs/SCAI_Health/jai16x3v was previously created and deleted; try a new run name","path":["upsertBucket"]}],"data":{"upsertBucket":null}}
2023-01-05 13:26:05,793 ERROR   SenderThread:25064 [internal_api.py:execute():212] 409 response executing GraphQL.
2023-01-05 13:26:05,793 ERROR   SenderThread:25064 [internal_api.py:execute():213] {"errors":[{"message":"run orbs/SCAI_Health/jai16x3v was previously created and deleted; try a new run name","path":["upsertBucket"]}],"data":{"upsertBucket":null}}
2023-01-05 13:26:05,796 ERROR   SenderThread:25064 [retry.py:__call__():154] Retry attempt failed:
Traceback (most recent call last):
  File "C:\Users\aaron\AppData\Local\Programs\Python\Python39\lib\site-packages\wandb\sdk\lib\retry.py", line 113, in __call__
    result = self._call_fn(*args, **kwargs)
  File "C:\Users\aaron\AppData\Local\Programs\Python\Python39\lib\site-packages\wandb\sdk\internal\internal_api.py", line 209, in execute
    return self.client.execute(*args, **kwargs)  # type: ignore
  File "C:\Users\aaron\AppData\Local\Programs\Python\Python39\lib\site-packages\wandb\vendor\gql-0.2.0\wandb_gql\client.py", line 52, in execute
    result = self._get_result(document, *args, **kwargs)
  File "C:\Users\aaron\AppData\Local\Programs\Python\Python39\lib\site-packages\wandb\vendor\gql-0.2.0\wandb_gql\client.py", line 60, in _get_result
    return self.transport.execute(document, *args, **kwargs)
  File "C:\Users\aaron\AppData\Local\Programs\Python\Python39\lib\site-packages\wandb\vendor\gql-0.2.0\wandb_gql\transport\requests.py", line 39, in execute
    request.raise_for_status()
  File "C:\Users\aaron\AppData\Local\Programs\Python\Python39\lib\site-packages\requests\models.py", line 1021, in raise_for_status
    raise HTTPError(http_error_msg, response=self)
requests.exceptions.HTTPError: 409 Client Error: Conflict for url: https://api.wandb.ai/graphql
2023-01-05 13:26:06,891 DEBUG   HandlerThread:25064 [handler.py:handle_request():139] handle_request: keepalive
2023-01-05 13:26:10,609 ERROR   SenderThread:25064 [internal_api.py:execute():212] 409 response executing GraphQL.
2023-01-05 13:26:10,610 ERROR   SenderThread:25064 [internal_api.py:execute():213] {"errors":[{"message":"run orbs/SCAI_Health/jai16x3v was previously created and deleted; try a new run name","path":["upsertBucket"]}],"data":{"upsertBucket":null}}
2023-01-05 13:26:11,990 DEBUG   HandlerThread:25064 [handler.py:handle_request():139] handle_request: keepalive
2023-01-05 13:26:17,028 DEBUG   HandlerThread:25064 [handler.py:handle_request():139] handle_request: keepalive
2023-01-05 13:26:19,741 ERROR   SenderThread:25064 [internal_api.py:execute():212] 409 response executing GraphQL.
2023-01-05 13:26:19,742 ERROR   SenderThread:25064 [internal_api.py:execute():213] {"errors":[{"message":"run orbs/SCAI_Health/jai16x3v was previously created and deleted; try a new run name","path":["upsertBucket"]}],"data":{"upsertBucket":null}}
2023-01-05 13:26:22,050 DEBUG   HandlerThread:25064 [handler.py:handle_request():139] handle_request: keepalive
2023-01-05 13:26:24,962 INFO    MainThread:25064 [internal.py:handle_exit():77] Internal process exited
2023-01-05 13:26:24,964 WARNING MsgRouterThr:25064 [router.py:message_loop():74] EOFError seen in message_loop
