2023-01-05 09:59:49,101 INFO    StreamThr :18172 [internal.py:wandb_internal():87] W&B internal server running at pid: 18172, started at: 2023-01-05 09:59:49.100075
2023-01-05 09:59:49,104 DEBUG   HandlerThread:18172 [handler.py:handle_request():139] handle_request: status
2023-01-05 09:59:49,108 DEBUG   SenderThread:18172 [sender.py:send_request():317] send_request: status
2023-01-05 09:59:49,116 DEBUG   SenderThread:18172 [sender.py:send():303] send: header
2023-01-05 09:59:49,116 INFO    WriterThread:18172 [datastore.py:open_for_write():75] open: C:\Users\aaron\CODING\SCAI\wandb\run-20230105_095949-4q582ys7\run-4q582ys7.wandb
2023-01-05 09:59:49,174 DEBUG   SenderThread:18172 [sender.py:send():303] send: run
2023-01-05 09:59:49,406 ERROR   SenderThread:18172 [internal_api.py:execute():212] 409 response executing GraphQL.
2023-01-05 09:59:49,407 ERROR   SenderThread:18172 [internal_api.py:execute():213] {"errors":[{"message":"run orbs/SCAI_Health/4q582ys7 was previously created and deleted; try a new run name","path":["upsertBucket"]}],"data":{"upsertBucket":null}}
2023-01-05 09:59:50,694 ERROR   SenderThread:18172 [internal_api.py:execute():212] 409 response executing GraphQL.
2023-01-05 09:59:50,694 ERROR   SenderThread:18172 [internal_api.py:execute():213] {"errors":[{"message":"run orbs/SCAI_Health/4q582ys7 was previously created and deleted; try a new run name","path":["upsertBucket"]}],"data":{"upsertBucket":null}}
2023-01-05 09:59:52,932 ERROR   SenderThread:18172 [internal_api.py:execute():212] 409 response executing GraphQL.
2023-01-05 09:59:52,933 ERROR   SenderThread:18172 [internal_api.py:execute():213] {"errors":[{"message":"run orbs/SCAI_Health/4q582ys7 was previously created and deleted; try a new run name","path":["upsertBucket"]}],"data":{"upsertBucket":null}}
2023-01-05 09:59:52,934 ERROR   SenderThread:18172 [retry.py:__call__():154] Retry attempt failed:
Traceback (most recent call last):
  File "C:\Users\aaron\AppData\Local\Programs\Python\Python39\lib\site-packages\wandb\sdk\lib\retry.py", line 113, in __call__
    result = self._call_fn(*args, **kwargs)
  File "C:\Users\aaron\AppData\Local\Programs\Python\Python39\lib\site-packages\wandb\sdk\internal\internal_api.py", line 209, in execute
    return self.client.execute(*args, **kwargs)  # type: ignore
  File "C:\Users\aaron\AppData\Local\Programs\Python\Python39\lib\site-packages\wandb\vendor\gql-0.2.0\wandb_gql\client.py", line 52, in execute
    result = self._get_result(document, *args, **kwargs)
  File "C:\Users\aaron\AppData\Local\Programs\Python\Python39\lib\site-packages\wandb\vendor\gql-0.2.0\wandb_gql\client.py", line 60, in _get_result
    return self.transport.execute(document, *args, **kwargs)
  File "C:\Users\aaron\AppData\Local\Programs\Python\Python39\lib\site-packages\wandb\vendor\gql-0.2.0\wandb_gql\transport\requests.py", line 39, in execute
    request.raise_for_status()
  File "C:\Users\aaron\AppData\Local\Programs\Python\Python39\lib\site-packages\requests\models.py", line 1021, in raise_for_status
    raise HTTPError(http_error_msg, response=self)
requests.exceptions.HTTPError: 409 Client Error: Conflict for url: https://api.wandb.ai/graphql
2023-01-05 09:59:54,226 DEBUG   HandlerThread:18172 [handler.py:handle_request():139] handle_request: keepalive
2023-01-05 09:59:58,098 ERROR   SenderThread:18172 [internal_api.py:execute():212] 409 response executing GraphQL.
2023-01-05 09:59:58,099 ERROR   SenderThread:18172 [internal_api.py:execute():213] {"errors":[{"message":"run orbs/SCAI_Health/4q582ys7 was previously created and deleted; try a new run name","path":["upsertBucket"]}],"data":{"upsertBucket":null}}
2023-01-05 09:59:59,331 DEBUG   HandlerThread:18172 [handler.py:handle_request():139] handle_request: keepalive
2023-01-05 10:00:04,387 DEBUG   HandlerThread:18172 [handler.py:handle_request():139] handle_request: keepalive
2023-01-05 10:00:08,232 ERROR   SenderThread:18172 [internal_api.py:execute():212] 409 response executing GraphQL.
2023-01-05 10:00:08,233 ERROR   SenderThread:18172 [internal_api.py:execute():213] {"errors":[{"message":"run orbs/SCAI_Health/4q582ys7 was previously created and deleted; try a new run name","path":["upsertBucket"]}],"data":{"upsertBucket":null}}
2023-01-05 10:00:09,450 DEBUG   HandlerThread:18172 [handler.py:handle_request():139] handle_request: keepalive
2023-01-05 10:00:14,496 DEBUG   HandlerThread:18172 [handler.py:handle_request():139] handle_request: keepalive
2023-01-05 10:00:19,561 DEBUG   HandlerThread:18172 [handler.py:handle_request():139] handle_request: keepalive
2023-01-05 10:00:24,605 DEBUG   HandlerThread:18172 [handler.py:handle_request():139] handle_request: keepalive
2023-01-05 10:00:24,902 ERROR   SenderThread:18172 [internal_api.py:execute():212] 409 response executing GraphQL.
2023-01-05 10:00:24,902 ERROR   SenderThread:18172 [internal_api.py:execute():213] {"errors":[{"message":"run orbs/SCAI_Health/4q582ys7 was previously created and deleted; try a new run name","path":["upsertBucket"]}],"data":{"upsertBucket":null}}
2023-01-05 10:00:29,651 DEBUG   HandlerThread:18172 [handler.py:handle_request():139] handle_request: keepalive
2023-01-05 10:00:34,701 DEBUG   HandlerThread:18172 [handler.py:handle_request():139] handle_request: keepalive
2023-01-05 10:00:39,764 DEBUG   HandlerThread:18172 [handler.py:handle_request():139] handle_request: keepalive
2023-01-05 10:00:44,815 DEBUG   HandlerThread:18172 [handler.py:handle_request():139] handle_request: keepalive
2023-01-05 10:00:50,893 DEBUG   HandlerThread:18172 [handler.py:handle_request():139] handle_request: poll_exit
2023-01-05 10:00:55,939 DEBUG   HandlerThread:18172 [handler.py:handle_request():139] handle_request: keepalive
2023-01-05 10:00:59,326 ERROR   SenderThread:18172 [internal_api.py:execute():212] 409 response executing GraphQL.
2023-01-05 10:00:59,326 ERROR   SenderThread:18172 [internal_api.py:execute():213] {"errors":[{"message":"run orbs/SCAI_Health/4q582ys7 was previously created and deleted; try a new run name","path":["upsertBucket"]}],"data":{"upsertBucket":null}}
2023-01-05 10:01:00,996 DEBUG   HandlerThread:18172 [handler.py:handle_request():139] handle_request: keepalive
2023-01-05 10:01:06,051 DEBUG   HandlerThread:18172 [handler.py:handle_request():139] handle_request: keepalive
2023-01-05 10:01:11,104 DEBUG   HandlerThread:18172 [handler.py:handle_request():139] handle_request: keepalive
2023-01-05 10:01:16,141 DEBUG   HandlerThread:18172 [handler.py:handle_request():139] handle_request: keepalive
2023-01-05 10:01:21,194 DEBUG   HandlerThread:18172 [handler.py:handle_request():139] handle_request: keepalive
2023-01-05 10:01:26,239 DEBUG   HandlerThread:18172 [handler.py:handle_request():139] handle_request: keepalive
2023-01-05 10:01:31,294 DEBUG   HandlerThread:18172 [handler.py:handle_request():139] handle_request: keepalive
2023-01-05 10:01:36,341 DEBUG   HandlerThread:18172 [handler.py:handle_request():139] handle_request: keepalive
2023-01-05 10:01:41,396 DEBUG   HandlerThread:18172 [handler.py:handle_request():139] handle_request: keepalive
2023-01-05 10:01:46,456 DEBUG   HandlerThread:18172 [handler.py:handle_request():139] handle_request: keepalive
2023-01-05 10:01:51,341 WARNING StreamThr :18172 [internal.py:is_dead():386] Internal process exiting, parent pid 28640 disappeared
2023-01-05 10:01:51,341 ERROR   StreamThr :18172 [internal.py:wandb_internal():146] Internal process shutdown.
2023-01-05 10:01:51,517 INFO    WriterThread:18172 [datastore.py:close():279] close: C:\Users\aaron\CODING\SCAI\wandb\run-20230105_095949-4q582ys7\run-4q582ys7.wandb
2023-01-05 10:01:51,517 INFO    HandlerThread:18172 [handler.py:finish():814] shutting down handler
2023-01-05 10:02:15,535 ERROR   SenderThread:18172 [internal_api.py:execute():212] 409 response executing GraphQL.
2023-01-05 10:02:15,535 ERROR   SenderThread:18172 [internal_api.py:execute():213] {"errors":[{"message":"run orbs/SCAI_Health/4q582ys7 was previously created and deleted; try a new run name","path":["upsertBucket"]}],"data":{"upsertBucket":null}}
2023-01-05 10:02:15,537 ERROR   StreamThr :18172 [internal.py:wandb_internal():162] Thread SenderThread:
Traceback (most recent call last):
  File "C:\Users\aaron\AppData\Local\Programs\Python\Python39\lib\site-packages\wandb\apis\normalize.py", line 26, in wrapper
    return func(*args, **kwargs)
  File "C:\Users\aaron\AppData\Local\Programs\Python\Python39\lib\site-packages\wandb\sdk\internal\internal_api.py", line 1515, in upsert_run
    response = self.gql(
  File "C:\Users\aaron\AppData\Local\Programs\Python\Python39\lib\site-packages\wandb\sdk\lib\retry.py", line 113, in __call__
    result = self._call_fn(*args, **kwargs)
  File "C:\Users\aaron\AppData\Local\Programs\Python\Python39\lib\site-packages\wandb\sdk\internal\internal_api.py", line 209, in execute
    return self.client.execute(*args, **kwargs)  # type: ignore
  File "C:\Users\aaron\AppData\Local\Programs\Python\Python39\lib\site-packages\wandb\vendor\gql-0.2.0\wandb_gql\client.py", line 52, in execute
    result = self._get_result(document, *args, **kwargs)
  File "C:\Users\aaron\AppData\Local\Programs\Python\Python39\lib\site-packages\wandb\vendor\gql-0.2.0\wandb_gql\client.py", line 60, in _get_result
    return self.transport.execute(document, *args, **kwargs)
  File "C:\Users\aaron\AppData\Local\Programs\Python\Python39\lib\site-packages\wandb\vendor\gql-0.2.0\wandb_gql\transport\requests.py", line 39, in execute
    request.raise_for_status()
  File "C:\Users\aaron\AppData\Local\Programs\Python\Python39\lib\site-packages\requests\models.py", line 1021, in raise_for_status
    raise HTTPError(http_error_msg, response=self)
requests.exceptions.HTTPError: 409 Client Error: Conflict for url: https://api.wandb.ai/graphql

During handling of the above exception, another exception occurred:

Traceback (most recent call last):
  File "C:\Users\aaron\AppData\Local\Programs\Python\Python39\lib\site-packages\wandb\sdk\internal\internal_util.py", line 49, in run
    self._run()
  File "C:\Users\aaron\AppData\Local\Programs\Python\Python39\lib\site-packages\wandb\sdk\internal\internal_util.py", line 100, in _run
    self._process(record)
  File "C:\Users\aaron\AppData\Local\Programs\Python\Python39\lib\site-packages\wandb\sdk\internal\internal.py", line 309, in _process
    self._sm.send(record)
  File "C:\Users\aaron\AppData\Local\Programs\Python\Python39\lib\site-packages\wandb\sdk\internal\sender.py", line 305, in send
    send_handler(record)
  File "C:\Users\aaron\AppData\Local\Programs\Python\Python39\lib\site-packages\wandb\sdk\internal\sender.py", line 797, in send_run
    self._init_run(run, config_value_dict)
  File "C:\Users\aaron\AppData\Local\Programs\Python\Python39\lib\site-packages\wandb\sdk\internal\sender.py", line 823, in _init_run
    server_run, inserted, server_messages = self._api.upsert_run(
  File "C:\Users\aaron\AppData\Local\Programs\Python\Python39\lib\site-packages\wandb\apis\normalize.py", line 28, in wrapper
    raise CommError(err.response, err)
wandb.errors.CommError: <Response [409]>
